Workbook
Name AmDGSF: #REF!
Name careareas: #REF!
Name CCbeds: #REF!
Name Comparison: #REF!
Name CVDGSF: #REF!
Name EDDGSF: #REF!
Name EDDGSF2: #REF!
Name ICUBeds: #REF!
Name ICUFlrs: #REF!
Name ImDGSF: #REF!
Name merge_loc: #REF!
Name MSBeds: #REF!
Name MSFlrs: #REF!
Name OncDGSF: #REF!
Name PCUFlrs: #REF!
Name PedsBeds: #REF!
Name PodQuantiity: #REF!
Name PodQuantity: #REF!
Name PrivBeds: #REF!
Name PTDGSF: #REF!
Name RXDGSF: #REF!
Name SURGDGSF: #REF!

Sheet Campus MASTER PLAN
B2: UPDATED: 11/07/2025
B4: Overall Melville Campus Master Plan
E6: Units | G6: Subtotal DGSF + MER | I6: GSF | K6: Notes
B8: PHASE 1 | P8: UNIONDALE | S8: DELTA
B10: HOSPITAL - Phase 1 | G10: ='Hospital Program TARGET_DESIGN'!M182 -> 0 | I10: ='Hospital Program TARGET_DESIGN'!M183 -> 1751415 | P10: 2300000 | S10: =I10-P10 -> -548585
C11: Licensed Beds | E11: ='Hospital Program TARGET_DESIGN'!K56 -> 568
C12: ORs (2 w/ Fixed Imaging) | E12: ='Hospital Program TARGET_DESIGN'!K15 -> 23
C13: Procedure Rooms + Imaging & Dialysis | E13: ='Hospital Program TARGET_DESIGN'!K28+'Hospital Program TARGET_DESIGN'!K36 -> 22
C14: ED Bays + Imaging | E14: ='Hospital Program TARGET_DESIGN'!K8 -> 73
B16: CUP (Central Utility Plant) | I16: 100000 | P16: 180000 | S16: =I16-P16 -> -80000
D18: HOSPITAL SUBTOTAL | I18: =SUM(I10:I17) -> 1851415 | P18: =SUM(P10:P17) -> 2480000 | S18: =SUM(S10:S17) -> -628585
B21: PARKING - HOSPITAL Phase 1 | E21: 2498 | I21: =E21*350 -> 874300 | K21: GSF Assume 350SF/Space | P21: 1200000 | S21: =I21-P21 -> -325700
D23: P1 PARKING SUBTOTAL | E23: =SUM(E17:E22) -> 2498 | I23: =SUM(I21:I22) -> 874300 | P23: =SUM(P21:P22) -> 1200000 | S23: =I23-P23 -> -325700
B26: PHASE 2
B28: ACADEMIC | I28: 45000 | P28: 120000 | S28: =I28-P28 -> -75000
C29: Teaching Spaces
C30: Staff/Admin
B32: ACADEMIC RESEARCH | I32: 45000 | P32: 80000 | S32: =I32-P32 -> -35000
C33: Dry Lab
C34: Office
B36: CORPORATE OFFICE | I36: 70000 | P36: 70000 | S36: =I36-P36 -> 0
C37: MCIT Offices
C38: RED+F Offices
C39: Human Resource Offices
C40: Finance + Billing Offices
C41: Other Support Offices
B43: RESIDENTIAL | E43: 240 | I43: 200000 | K43: 11/20/2025 Beau Everett Comments | P43: 200000 | S43: =I43-P43 -> 0
C44: Staff Housing | K44: 24 Students / Class = +/-80
C45: Student Housing | K45: Post Opp + Faculty = 0
K46: House Staff = 0 (change in NYU Operation)
B47: MEDICAL OFFICE BUILDING (MOB) | I47: 125000 | P47: 25000 | S47: =I47-P47 -> 100000
C48: Physician Offices
C49: Practice Space
D51: PHASE 2 SUBTOTAL | I51: =I28+I32+I36+I43+I47 -> 485000 | P51: =P28+P32+P36+P43+P47 -> 495000 | S51: =S28+S32+S36+S43+S47 -> -10000
B54: PARKING - ACADEMIC | E54: 131 | I54: =E54*350 -> 45850 | K54: GSF Assume 350SF/Space | P54: 32000 | S54: =I54-P54 -> 13850
B55: PARKING - CORPORATE OFFICE | E55: 137 | I55: =E55*350 -> 47950 | K55: GSF Assume 350SF/Space | P55: 61800 | S55: =I55-P55 -> -13850
B56: PARKING - RESIDENTIAL | E56: 295 | I56: =E56*350 -> 103250 | K56: GSF Assume 350SF/Space | P56: 85000 | S56: =I56-P56 -> 18250
B57: PARKING - MOB | E57: 448 | I57: =E57*350 -> 156800 | K57: GSF Assume 350SF/Space | P57: 27600 | S57: =I57-P57 -> 129200
D59: P2 PARKING SUBTOTAL | E59: =SUM(E54:E58) -> 1011 | I59: =SUM(I54:I58) -> 353850 | P59: =SUM(P54:P58) -> 206400 | S59: =I59-P59 -> 147450
B62: PHASE 3
...

Sheet Hospital Program TARGET_DESIGN
A1: COLOR | C1: DEPARTMENT | D1: DIVISION | E1: ROOM NAME | K1: KEY UNIT | S1: Factor_DGSF | T1: DGSF+ | X1: Factor_DGSF | Y1: FGSF+ | AO1: DESIGN
BJ2: Notes from NYU Strategy July 2025
D3: #UPDATED: 11/07/2025 - EC UPDATE REQ'D - Central Sterile | H3: MELVILLE | K3: Key Room DGSF Program | O3: Room-by-Room Program | AO3: CONCEPT | AS3: TARGET | AX3: UNIONDALE - 724 Beds | BE3: UNIONDALE - 854 Beds | BR3: UNIONDALE
D4: DO NOT CHANGE LOCATION OF ROWS A, C-D, K, P-Q, U-V, AL | H4: 2025-09-09 Steering | K4: MELVILLE - 574 Beds | O4: For Reference Only | AO4: DESIGN | AS4: DELTA | AX4: Reference ONLY | BE4: Reference ONLY
H5: Current State KPU Demand | I5: 10 Yr KPU Demand | K5: Key Rooms | L5: Target DGSF/Room | M5: DGSF | O5: DGSF/Room | P5: DGSF | S5: Target DGSF Planning DGSF x 1.1 Factor | X5: Target FGSF Planning DGSF x 1.25/1.3 Factor | AC5: Program GSF Planning DGSF x 1.5 Factor | AH5: % DGSF | AJ5: DGSF Nearest (1,000) | AO5: DGSF | AQ5: LEVEL | AS5: DGSF | BA5: DELTA | BE5: 05-20-2024 Concept Plan DGSF | BH5: DELTA | BR5: Key Rooms | BS5: Target DGSF/Room | BT5: DGSF
B6: A | C6: EMERGENCY CARE SERVICES | M6: =M7+M11 -> 73100 | P6: =P7+P11 -> 72638 | S6: 1.1 | T6: =S6*M6 -> 80410 | X6: 1.25 | Y6: =X6*M6 -> 91375 | AC6: 1.5 | AD6: =AC6*M6 -> 109650 | AH6: =_xlfn.PERCENTOF(M6,M176) -> 0.062606521 | AJ6: =MROUND(M6,1000) -> 73000 | AO6: =AO7+AO11 -> 73100 | AS6: =AO6-T6 -> -7310 | AX6: =AX7+AX11 -> 90400 | BA6: =M6-AX6 -> -17300 | BE6: =BE7+BE11 -> 107128 | BH6: =M6-BE6 -> -34028 | BT6: =BT7+BT11 -> 90400
B7: 01 | D7: Emergency Care Services (ED) | H7: =H8 -> 54 | I7: =I8 -> 73 | K7: =K8 -> 73 | L7: =M7/K7 -> 869.86301 | M7: 63500 | O7: =P7/K7 -> 864.69863 | P7: 63123 | T7: =S6*M7 -> 69850 | Y7: =X6*M7 -> 79375 | AD7: =AC6*M7 -> 95250 | AO7: =SUM(AO8:AO9) -> 63500 | AX7: 80000 | BE7: 96568 | BT7: =BT8 -> 80000
E8: Treatment positions | H8: 54 | I8: 73 | K8: 73 | L8: 865 | M8: =L8*K8 -> 63145 | T8: =S6*M8 -> 69459.5 | Y8: =X6*M8 -> 78931.25 | AD8: =AC6*M8 -> 94717.5 | AJ8: =MROUND(M8,1000) -> 63000 | AO8: 59500 | AQ8: L1 | AS8: =AO8-T8 -> -9959.5 | BR8: 100 | BS8: 800 | BT8: =BS8*BR8 -> 80000
E9: ED Imaging | H9: 8 | I9: 8 | K9: 8 | L9: incl | AO9: 4000 | AQ9: L1 | AS9: =AO9-T9 -> 4000 | BR9: 8 | BS9: incl
D11: Observation | H11: =H12 -> 16 | I11: =I12 -> 16 | K11: =K12 -> 16 | L11: =M11/K11 -> 600 | M11: =M12 -> 9600 | O11: =P11/K11 -> 594.6875 | P11: 9515 | T11: =S6*M11 -> 10560 | Y11: =X6*M11 -> 12000 | AD11: =AC6*M11 -> 14400 | AO11: =AO12 -> 9600 | AX11: 10400 | BE11: 10560 | BR11: =BR12 -> 16 | BT11: =BT12 -> 10400
B12: 10d | E12: Patient Units_Observation | H12: 16 | I12: 16 | K12: 16 | L12: 600 | M12: =L12*K12 -> 9600 | T12: =+S6*M12 -> 10560 | Y12: =+X6*M12 -> 12000 | AD12: =+AC6*M12 -> 14400 | AJ12: =MROUND(M12,1000) -> 10000 | AO12: 9600 | AQ12: L1 | AS12: =AO12-T12 -> -960 | BR12: 16 | BS12: 650 | BT12: =BS12*BR12 -> 10400
B14: B | C14: DIAGNOSTIC AND TREATMENT | M14: =SUM(M15,M40,M43,M20,M49,M52)+M28+M36 -> 300700 | P14: =SUM(P15:P54) -> 304382 | S14: 1.1 | T14: =S14*M14 -> 330770 | X14: 1.25 | Y14: =X14*M14 -> 375875 | AC14: 1.5 | AD14: =AC14*M14 -> 451050 | AH14: =_xlfn.PERCENTOF(M14,M176) -> 0.25753462 | AJ14: =MROUND(M14,1000) -> 301000 | AO14: =SUM(AO15,AO40,AO43,AO20,AO49,AO52)+AO28+AO36 -> 447200 | AS14: =AO14-T14 -> 116430 | AX14: =SUM(AX15,AX40,AX43,AX20,AX49,AX52)+AX28+AX36 -> 310650 | BA14: =M14-AX14 -> -9950 | BE14: =SUM(BE15,BE40,BE43,BE20,BE49,BE52)+BE28+BE36 -> 355300 | BH14: =M14-BE14 -> -54600 | BT14: =SUM(BT15,BT40,BT43,BT20,BT49,BT52) -> 1173950
B15: 02a | D15: Surgery & Procedures | H15: =SUM(H16:H18) -> 20 | I15: =SUM(I16:I18) -> 23 | K15: =SUM(K16:K18) -> 23 | L15: =M15/K15 -> 4417.3913 | M15: =SUM(M16:M18) -> 101600 | O15: =P15/K15 -> 4592.087 | P15: 105618 | T15: =S14*M15 -> 111760 | Y15: =X14*M15 -> 127000 | AD15: =AC14*M15 -> 152400 | AJ15: =MROUND(M15,1000) -> 102000 | AO15: =SUM(AO16:AO18) -> 101600 | AX15: 114200 | BE15: 160907 | BR15: =SUM(BR16:BR35)-#REF! -> #REF! | BT15: =SUM(BT16:BT35) -> 768300
E16: General ORs | H16: 20 | I16: 23 | K16: 15 | L16: 4200 | M16: =L16*K16 -> 63000 | T16: =S14*M16 -> 69300 | Y16: =X14*M16 -> 78750 | AD16: =AC14*M16 -> 94500 | AO16: 63000 | AQ16: L4 | AS16: =AO16-T16 -> -6300 | BR16: 18 | BS16: 4200 | BT16: =BS16*BR16 -> 75600
E17: Hybrid/Interoperative OR + MRI | K17: 2 | L17: 5200 | M17: =L17*K17 -> 10400 | T17: =S14*M17 -> 11440 | Y17: =X14*M17 -> 13000 | AD17: =AC14*M17 -> 15600 | AO17: 10400 | AQ17: L4 | AS17: =AO17-T17 -> -1040 | BR17: 2 | BS17: 5200 | BT17: =BS17*BR17 -> 10400
E18: Other ORs with fixed Imaging | K18: 6 | L18: 4700 | M18: =L18*K18 -> 28200 | T18: =S14*M18 -> 31020 | Y18: =X14*M18 -> 35250 | AD18: =AC14*M18 -> 42300 | AO18: 28200 | AQ18: L4 | AS18: =AO18-T18 -> -2820 | BJ18: Providing "bigger box" for future needs | BR18: 6 | BS18: 4700 | BT18: =BS18*BR18 -> 28200
B20: 03a | D20: Imaging & Other Diagnostic Services | H20: =SUM(H21:H33) -> 30 | I20: =SUM(I21:I33) -> 48 | K20: =SUM(K21:K26) -> 16 | L20: =M20/K20 -> 1850 | M20: =SUM(M21:M26) -> 29600 | O20: =P20/K20 -> 1927.5 | P20: 30840 | T20: =S14*M20 -> 32560 | Y20: =X14*M20 -> 37000 | AD20: =AC14*M20 -> 44400 | AJ20: =MROUND(M20,1000) -> 30000 | AO20: =SUM(AO21:AO33) -> 178200 | AX20: 29850 | BE20: 27005 | BR20: =SUM(BR21:BR33) -> 230 | BT20: =SUM(BT21:BT33) -> 327050
E21: CT | H21: 2 | I21: 3 | K21: 3 | L21: 1850 | M21: =L21*K21 -> 5550 | T21: =S14*M21 -> 6105 | Y21: =X14*M21 -> 6937.5 | AD21: =AC14*M21 -> 8325 | AO21: 5550 | AQ21: L3 | AS21: =AO21-T21 -> -555 | BR21: 3 | BS21: 1750 | BT21: =BS21*BR21 -> 5250
E22: MRI | H22: 2 | I22: 2 | K22: 2 | L22: 1850 | M22: =L22*K22 -> 3700 | T22: =S14*M22 -> 4070 | Y22: =X14*M22 -> 4625 | AD22: =AC14*M22 -> 5550 | AO22: 3700 | AQ22: L3 | AS22: =AO22-T22 -> -370 | BR22: 2 | BS22: 1750 | BT22: =BS22*BR22 -> 3500
E23: PET | H23: 1 | I23: 1 | K23: 1 | L23: 1850 | M23: =L23*K23 -> 1850 | T23: =S14*M23 -> 2035 | Y23: =X14*M23 -> 2312.5 | AD23: =AC14*M23 -> 2775 | AO23: 1850 | AQ23: L3 | AS23: =AO23-T23 -> -185 | BR23: 1 | BS23: 1750 | BT23: =BS23*BR23 -> 1750
E24: Nuclear Medicine | H24: 2 | I24: 3 | K24: 3 | L24: 1850 | M24: =L24*K24 -> 5550 | T24: =S14*M24 -> 6105 | Y24: =X14*M24 -> 6937.5 | AD24: =AC14*M24 -> 8325 | AO24: 5550 | AQ24: L3 | AS24: =AO24-T24 -> -555 | BR24: 3 | BS24: 1500 | BT24: =BS24*BR24 -> 4500
E25: Ultrasound | H25: 3 | I25: 4 | K25: 4 | L25: 1850 | M25: =L25*K25 -> 7400 | T25: =S14*M25 -> 8140 | Y25: =X14*M25 -> 9250 | AD25: =AC14*M25 -> 11100 | AO25: 7400 | AQ25: L3 | AS25: =AO25-T25 -> -740 | BR25: 4 | BS25: 1750 | BT25: =BS25*BR25 -> 7000
E26: XR/Fluoroscopic Room | H26: 2 | I26: 3 | K26: 3 | L26: 1850 | M26: =L26*K26 -> 5550 | T26: =S14*M26 -> 6105 | Y26: =X14*M26 -> 6937.5 | AD26: =AC14*M26 -> 8325 | AO26: 5550 | AQ26: L3 | AS26: =AO26-T26 -> -555 | BR26: 3 | BS26: 1750 | BT26: =BS26*BR26 -> 5250
B28: 03b | 06 | D28: Procedure - Interventional Radiology | Cardiovascular | H28: =SUM(H29:H32) -> 9 | I28: =SUM(I29:I32) -> 16 | K28: =SUM(K29:K32) -> 16 | L28: =M28/K28 -> 4725 | M28: =SUM(M29:M33) -> 75600 | O28: =P28/K28 -> 5073 | P28: =37144+44024 -> 81168 | T28: =S14*M28 -> 83160 | Y28: =X14*M28 -> 94500 | AD28: =AC14*M28 -> 113400 | AJ28: =MROUND(M28,1000) -> 76000 | AO28: =SUM(AO29:AO32) -> 73000 | AX28: 73000 | BE28: 50101 | BR28: =SUM(BR29:BR41)-BR32 -> 191 | BT28: =SUM(BT29:BT41) -> 224200
E29: Cath/EP (4 ea) | H29: 6 | I29: 8 | K29: 8 | L29: 4700 | M29: =L29*K29 -> 37600 | T29: =S14*M29 -> 41360 | Y29: =X14*M29 -> 47000 | AD29: =AC14*M29 -> 56400 | AO29: 37600 | AQ29: L3 | AS29: =AO29-T29 -> -3760 | BR29: 8 | BS29: 4700 | BT29: =BS29*BR29 -> 37600
E30: Interventional Radiology | H30: 2 | I30: 6 | K30: 6 | L30: 4700 | M30: =L30*K30 -> 28200 | T30: =S14*M30 -> 31020 | Y30: =X14*M30 -> 35250 | AD30: =AC14*M30 -> 42300 | AO30: 28200 | AQ30: L3 | AS30: =AO30-T30 -> -2820 | BR30: 6 | BS30: 4700 | BT30: =BS30*BR30 -> 28200
E31: Minor Procedure Room (IR) | H31: 1 | I31: 1 | K31: 1 | L31: 3600 | M31: =L31*K31 -> 3600 | T31: =S14*M31 -> 3960 | Y31: =X14*M31 -> 4500 | AD31: =AC14*M31 -> 5400 | AO31: 3600 | AQ31: L3 | AS31: =AO31-T31 -> -360
E32: Minor Procedure Room (EP) | I32: 1 | K32: 1 | L32: 3600 | M32: =L32*K32 -> 3600 | T32: =S14*M32 -> 3960 | Y32: =X14*M32 -> 4500 | AD32: =AC14*M32 -> 5400 | AO32: 3600 | AQ32: L3 | AS32: =AO32-T32 -> -360 | BR32: 2 | BS32: 3600 | BT32: =BS32*BR32 -> 7200
E33: Non-Invasive Cardiology | K33: 7 | M33: 2600 | T33: =S14*M33 -> 2860 | Y33: =X14*M33 -> 3250 | AD33: =AC14*M33 -> 3900 | AO33: 2600 | AQ33: L3 | AS33: =AO33-T33 -> -260 | BR33: 7 | BT33: 2600
B36: 02b | D36: Procedure - Endo | H36: =SUM(H37) -> 5 | I36: =SUM(I37) -> 6 | K36: =SUM(K37) -> 6 | L36: =M36/K36 -> 2300 | M36: =SUM(M37) -> 13800 | O36: =P36/K36 -> 2358.5 | P36: 14151 | T36: =S14*M36 -> 15180 | Y36: =X14*M36 -> 17250 | AD36: =AC14*M36 -> 20700 | AJ36: =MROUND(M36,1000) -> 14000 | AO36: =SUM(AO37) -> 13800 | AX36: 15000 | BE36: 19215 | BR36: =SUM(BR39:BR47)-BR42 -> 93 | BT36: =SUM(BT39:BT47) -> 86800
E37: Bronch/Endo | H37: 5 | I37: 6 | K37: 6 | L37: 2300 | M37: =L37*K37 -> 13800 | T37: =S14*M37 -> 15180 | Y37: =X14*M37 -> 17250 | AD37: =AC14*M37 -> 20700 | AO37: 13800 | AQ37: L4 | AS37: =AO37-T37 -> -1380 | BR37: 5 | BS37: 3000 | BT37: =BS37*BR37 -> 15000
B40: 10c | D40: Post Procedural Care Unit | H40: =H41 -> 0 | I40: =I41 -> 0 | K40: 36 | L40: =M40/K40 -> 650 | M40: =M41 -> 23400 | O40: =P40/K40 -> 506.58333 | P40: 18237 | T40: =S14*M40 -> 25740 | Y40: =X14*M40 -> 29250 | AD40: =AC14*M40 -> 35100 | AJ40: =MROUND(M40,1000) -> 23000 | AO40: =AO41 -> 23400 | AX40: 23400 | BE40: 22739 | BR40: =BR41 -> 36 | BT40: =BT41 -> 23400
E41: Post Procedural Observation (PPCU) | K41: 36 | L41: 650 | M41: =K41*L41 -> 23400 | T41: =S14*M41 -> 25740 | Y41: =X14*M41 -> 29250 | AD41: =AC14*M41 -> 35100 | AO41: 23400 | AQ41: L3 | AS41: =AO41-T41 -> -2340 | BR41: 36 | BS41: 650 | BT41: =BR41*BS41 -> 23400
B43: 07a | D43: Labor & Delivery | H43: =SUM(H44:H46) -> 31 | I43: =SUM(I44:I46) -> 30 | K43: 16 | L43: =M43/K43 -> 2468.75 | M43: =SUM(M44:M46) -> 39500 | O43: =P43/K43 -> 2268 | P43: 36288 | T43: =S14*M43 -> 43450 | Y43: =X14*M43 -> 49375 | AD43: =AC14*M43 -> 59250 | AJ43: =MROUND(M43,1000) -> 40000 | AO43: =SUM(AO44:AO46) -> 40000 | AX43: 40000 | BE43: 53435 | BT43: 40000
E44: Labor and Delivery | H44: 16 | I44: 16 | K44: 16 | L44: 1950 | M44: =K44*L44 -> 31200 | T44: =S14*M44 -> 34320 | Y44: =X14*M44 -> 39000 | AD44: =AC14*M44 -> 46800 | AO44: 31200 | AQ44: L7 | AS44: =AO44-T44 -> -3120 | BR44: 16 | BS44: 1950
E45: C-Section | H45: 4 | I45: 4 | K45: 4 | L45: incl | M45: =4400-500 -> 3900 | T45: =S14*M45 -> 4290 | Y45: =X14*M45 -> 4875 | AD45: =AC14*M45 -> 5850 | AO45: 4400 | AQ45: L7 | AS45: =AO45-T45 -> 110 | BR45: 5 | BS45: incl
E46: Triage | H46: 11 | I46: 10 | K46: 10 | L46: incl | M46: 4400 | T46: =S14*M46 -> 4840 | Y46: =X14*M46 -> 5500 | AD46: =AC14*M46 -> 6600 | AO46: 4400 | AQ46: L7 | AS46: =AO46-T46 -> -440
B49: 15 | D49: Dialysis | H49: =SUM(H50:H52) -> 6 | I49: =SUM(I50:I52) -> 10 | K49: =K50 -> 10 | L49: =M49/K49 -> 520 | M49: =M50 -> 5200 | O49: =P49/K49 -> 520 | P49: 5200 | T49: =S14*M49 -> 5720 | Y49: =X14*M49 -> 6500 | AD49: =AC14*M49 -> 7800 | AJ49: =MROUND(M49,1000) -> 5000 | AO49: =AO50 -> 5200 | AX49: 5200 | BE49: 7010 | BR49: 10 | BT49: =BT50 -> 5200
E50: Dialysis (8 Chairs + 2 ISO Rooms) | H50: 6 | I50: 10 | K50: 10 | L50: 520 | M50: =K50*L50 -> 5200 | T50: =S14*M50 -> 5720 | Y50: =X14*M50 -> 6500 | AD50: =AC14*M50 -> 7800 | AO50: 5200 | AQ50: L3 | AS50: =AO50-T50 -> -520 | BR50: 10 | BS50: 520 | BT50: =BR50*BS50 -> 5200
B52: 05 | D52: Radiation Oncology | H52: =H53 -> 0 | I52: =I53 -> 0 | K52: 2 | L52: =M52/K52 -> 6000 | M52: =M53 -> 12000 | O52: =P52/K52 -> 6440 | P52: 12880 | T52: =S14*M52 -> 13200 | Y52: =X14*M52 -> 15000 | AD52: =AC14*M52 -> 18000 | AJ52: =MROUND(M52,1000) -> 12000 | AO52: =AO53 -> 12000 | AX52: 10000 | BE52: 14888 | BR52: 1 | BT52: =BT53 -> 10000
...

Sheet OR & Procedure - Chunks
A2: Extrapoloated from Uniondale Room-by-Room Program from Ewing Cole 2024-05
A5: OR & Procedure Program Groups | B5: Uniondale Key Rooms | C5: NSF | D5: % | E5: Current Key Rooms | F5: DGSF | G5: % | H5: DGSF x1.1 | J5: HQ Program "Chunks" | K5: DGSF | M5: Planhing DGSF | Q5: Planning DGSF x1.1
M6: L2 | N6: L3 | O6: L4 | Q6: L2 | R6: L3 | S6: L4
A8: Surgery / ORs | C8: =SUM(C9:C15) -> 74149 | D8: =C8/C$8 -> 1 | F8: ='Hospital Program TARGET_DESIGN'!M15 -> 101600 | G8: =F8/F$8 -> 1 | H8: =F8*1.1 -> 111760 | J8: Surgery / ORs | K8: =SUM(K9:K12) -> 56443.226 | O8: =K8 -> 56443.226 | S8: =O8*1.1 -> 62087.549
A9: Patient Intake Area | C9: 2990 | D9: =C9/C$8 -> 0.040324212 | F9: =F$8*D9 -> 4096.9399 | G9: =F9/F$8 -> 0.040324212 | J9: Intake | K9: see below
A10: Operating Rooms | B10: 27 | C10: 25385 | D10: =C10/C$8 -> 0.34235121 | E10: ='[1]Hospital Program Comparison'!P14 -> 23 | F10: =F$8*D10 -> 34782.883 | G10: =F10/F$8 -> 0.34235121 | J10: Ors & OR Support | K10: =F10+F12+F13 -> 56443.226
A11: Pre/Post (3 per OR) | B11: 82 | C11: 20120 | D11: =C11/C$8 -> 0.27134553 | F11: =F$8*D11 -> 27568.706 | G11: =F11/F$8 -> 0.27134553 | J11: Pre/Post | K11: see below
A12: OR Support (with/adjacent to ORs) | C12: 14348 | D12: =C12/C$8 -> 0.19350227 | F12: =F$8*D12 -> 19659.831 | G12: =F12/F$8 -> 0.19350227 | J12: Staff Support | K12: see below
A13: OR Satellite Lab and Pharmacy | C13: =840+620 -> 1460 | D13: =C13/C$8 -> 0.019690083 | F13: =F$8*D13 -> 2000.5125 | G13: =F13/F$8 -> 0.019690083
A14: OR Staff Support | C14: 9846 | D14: =C14/C$8 -> 0.13278669 | F14: =F$8*D14 -> 13491.127 | G14: =F14/F$8 -> 0.13278669
A17: Imaging | C17: 21490 | D17: =C17/C$17 -> 1 | F17: ='Hospital Program TARGET_DESIGN'!M20 -> 29600 | G17: =F17/F$17 -> 1 | H17: =F17*1.1 -> 32560 | J17: Imaging | K17: =SUM(K18:K19) -> 28029.781 | N17: =K17 -> 28029.781 | R17: =N17*1.1 -> 30832.759
A18: Patient Intake Area | C18: 1140 | D18: =C18/C$17 -> 0.053047929 | F18: =F$17*D18 -> 1570.2187 | G18: =F18/F$17 -> 0.053047929 | J18: Intake | K18: see below
A19: Imaging | C19: =C17-C18 -> 20350 | D19: =C19/C$17 -> 0.94695207 | F19: =F$17*D19 -> 28029.781 | G19: =F19/F$17 -> 0.94695207 | J19: Imaging | K19: =F19 -> 28029.781
A22: Procedure: Endoscopy | C22: 8810 | D22: =C22/C$22 -> 1 | F22: ='Hospital Program TARGET_DESIGN'!M36 -> 13800 | G22: =F22/F$22 -> 1 | H22: =F22*1.1 -> 15180 | J22: Endo | K22: =SUM(K23:K25) -> 6962.6561 | O22: =K22 -> 6962.6561 | S22: =O22*1.1 -> 7658.9217
A23: Patient Intake Area | C23: 580 | D23: =C23/C$22 -> 0.065834279 | F23: =F$22*D23 -> 908.51305 | G23: =F23/F$22 -> 0.065834279 | J23: Intake | K23: see below
A24: Endo Rooms & Support | B24: 6 | C24: =C22-C23-C25-C26 -> 4445 | D24: =C24/C$22 -> 0.5045403 | E24: 6 | F24: =F$22*D24 -> 6962.6561 | G24: =F24/F$22 -> 0.5045403 | J24: Endo Rooms & Support | K24: =F24 -> 6962.6561
A25: Endo Pre/Post (3 per OR) | B25: 18 | C25: 3425 | D25: =C25/C$22 -> 0.38876277 | F25: =F$22*D25 -> 5364.9262 | G25: =F25/F$22 -> 0.38876277 | J25: Pre/Post | K25: see below
A26: Endo Staff Suport (can be co-located with OR Staff) | C26: 360 | D26: =C26/C$22 -> 0.040862656 | F26: =F$22*D26 -> 563.90465 | G26: =F26/F$22 -> 0.040862656 | J26: Staff Support | K26: see below
A29: Procedure: Cardiovascular | C29: =SUM(C30:C36) -> 26815 | D29: =C29/C$29 -> 1 | F29: ='Hospital Program TARGET_DESIGN'!M29+'Hospital Program TARGET_DESIGN'!M32+'Hospital Program TARGET_DESIGN'!M33 -> 43800 | G29: =F29/F$29 -> 1 | H29: =(F29+F38)*1.1 -> 83160 | J29: Procedure Platform (IR + Cath/EP) | K29: =SUM(K30:K32) -> 42872.084 | N29: =K29 -> 42872.084 | R29: =N29*1.1 -> 47159.292
A30: Patient Intake Area | C30: 1540 | D30: =C30/C$29 -> 0.057430543 | F30: =F$29*D30 -> 2515.4578 | G30: =F30/F$29 -> 0.057430543 | J30: Intake | K30: see below
A31: Cath/EP | B31: 9 | C31: 10805 | D31: =C31/C$29 -> 0.40294611 | E31: 8 | F31: =F$29*D31 -> 17649.04 | G31: =F31/F$29 -> 0.40294611 | J31: Cath/EP + IR Rooms & Support | K31: =F31+F34+F40+F42+F33 -> 42872.084
A32: Pre/Post (3 per OR) | B32: 28 | C32: 8235 | D32: =C32/C$29 -> 0.30710423 | F32: =F$29*D32 -> 13451.165 | G32: =F32/F$29 -> 0.30710423 | J32: Pre/Post | K32: see below
A33: Noninvasive Cardiology Diagnostics | C33: 820 | D33: =C33/C$29 -> 0.030579899 | F33: =F$29*D33 -> 1339.3996 | G33: =F33/F$29 -> 0.030579899 | J33: Staff Support | K33: see below
A34: Procedure Room Support (with/adjacent to PRs) | C34: 3325 | D34: =C34/C$29 -> 0.12399776 | F34: =F$29*D34 -> 5431.102 | G34: =F34/F$29 -> 0.12399776
A35: Staff Support | C35: 2090 | D35: =C35/C$29 -> 0.077941451 | F35: =F$29*D35 -> 3413.8355 | G35: =F35/F$29 -> 0.077941451 | AB35: x
J36: Prep/Post | K36: =SUM(K37:K39) -> 55684.798 | N36: =K39 -> 22751.165 | O36: =K37+K38 -> 32933.632 | R36: =N36*1.1 -> 25026.282 | S36: =O36*1.1 -> 36226.996
J37: OR Pre/Post | K37: =F11 -> 27568.706
A38: Procedure: Interventional Radiology | C38: =SUM(C39:C43) -> 31270 | D38: =C38/C$38 -> 1 | F38: ='Hospital Program TARGET_DESIGN'!M30+'Hospital Program TARGET_DESIGN'!M32 -> 31800 | G38: =F38/F$38 -> 1 | H38: incl. above | J38: Endo Pre/Post | K38: =F25 -> 5364.9262
A39: Patient Intake Area | C39: 1665 | D39: =C39/C$38 -> 0.053245923 | F39: =F$38*D39 -> 1693.2203 | G39: =F39/F$38 -> 0.053245923 | J39: Procefure Pre/Post | K39: =F32+F41 -> 22751.165
A40: Procedure Rooms | B40: 11 | C40: 12760 | D40: =C40/C$38 -> 0.40805884 | E40: 6 | F40: =F$38*D40 -> 12976.271 | G40: =F40/F$38 -> 0.40805884
A41: Pre/Post (3 per OR) | B41: 30 | C41: 9145 | D41: =C41/C$38 -> 0.29245283 | F41: =F$38*D41 -> 9300 | G41: =F41/F$38 -> 0.29245283
A42: IR Support (with/adjacent to IR) | C42: 5385 | D42: =C42/C$38 -> 0.17220979 | F42: =F$38*D42 -> 5476.2712 | G42: =F42/F$38 -> 0.17220979
A43: Staff Support | C43: 2315 | D43: =C43/C$38 -> 0.074032619 | F43: =F$38*D43 -> 2354.2373 | G43: =F43/F$38 -> 0.074032619
A45: Dialysis | F45: =F46 -> 5200 | G45: =G46 -> 1 | H45: =F45*1.1 -> 5720 | J45: Dialysis | K45: =K46 -> 5200 | N45: =K45 -> 5200 | R45: =N45*1.1 -> 5720
A46: Rooms/Chairs | E46: 10 | F46: ='Hospital Program TARGET_DESIGN'!M49 -> 5200 | G46: =F46/F45 -> 1 | J46: 10 Chair Department | K46: =F46 -> 5200
F49: DGSF | H49: DGSF x 1.1 | J49: Staff Support (all ORs/Procedure) | K49: =SUM(K50:K52) -> 19823.105 | M49: =K49*0.8 -> 15858.484 | N49: =K49*0.1 -> 1982.3105 | O49: =K49*0.1 -> 1982.3105 | Q49: =M49*1.1 -> 17444.332 | R49: =N49*1.1 -> 2180.5415 | S49: =O49*1.1 -> 2180.5415
E50: L3 | F50: =F17+F29+F38+F45 -> 110400 | H50: =H17+H29+H45 -> 121440 | J50: Staff Support Surgery/Ors | K50: =F14 -> 13491.127
E51: L4 | F51: =F22+F8 -> 115400 | H51: =H22+H8 -> 126940 | J51: Staff Support Endo | K51: =F26 -> 563.90465
J52: Staff Suport Procedure | K52: =F43+F35 -> 5768.0728
F53: =F50*1.3 -> 143520
...

Sheet Hospital Program per Floor
B2: UPDATED: 11/07/2025
B4: Phase 1 Buildings
B6: Hospital | H6: Inpatient Room DGSF (576 Beds) | L6: Non-Patient Room DGSF
B7: Level | C7: Program | D7: Total GSF Covered | E7: Total GSF Enclosed | F7: MEP | G7: Total FGSF | H7: FGSF | I7: xFGSF (Inpatient) | J7: Subtotal Fitout DGSF (Inpatient) | K7: Inpatient | L7: FGSF | M7: xFGSF (Podium) | N7: Subtotal Fitout DGSF (Podium) | O7: ED | P7: D&T | Q7: Admin & Staff Support | R7: Clinical Support | S7: Building Support | T7: Public Support | U7: Unassigned Area
J9: =SUM(K9:Y9) -> 0 | K9: 0 | N9: =SUM(O9:AA9) -> 0 | O9: 0 | P9: 0 | Q9: 0 | R9: 0 | S9: 0 | T9: 0 | U9: 0
B10: 14 Roof | C10: Elev. Bulkhead (trauma + service) | D10: 0 | E10: =H10+F10+L10 -> 12000 | F10: 12000 | J10: =SUM(K10:Y10) -> 0 | K10: 0 | N10: =SUM(O10:AA10) -> 0 | O10: 0 | P10: 0 | Q10: 0 | R10: 0 | S10: 0 | T10: 0 | U10: 0
B11: 13 Roof | C11: Mechanical | D11: 0 | E11: =H11+F11+L11 -> 64000 | F11: 64000 | J11: =SUM(K11:Y11) -> 0 | K11: 0 | N11: =SUM(O11:AA11) -> 0 | O11: 0 | P11: 0 | Q11: 0 | R11: 0 | S11: 0 | T11: 0 | U11: 0
B12: 12 | C12: Inpatient Units (72 Beds) | D12: 0 | E12: =H12+F12+L12 -> 88164 | F12: 0 | G12: =SUM(H12,L12) -> 88164 | H12: =(I12*K12) -> 88164 | I12: 1.3 | J12: =SUM(K12) -> 67818.462 | K12: ='Hospital Program TARGET_DESIGN'!AO57/6.5 -> 67818.462 | L12: =(SUM(U12,O12,P12,Q12,R12,S12,T12)*M12) -> 0 | M12: 1.25 | N12: =SUM(O12:AA12) -> 0 | O12: 0 | P12: 0 | Q12: 0 | R12: 0 | S12: 0 | T12: 0 | U12: 0
B13: 11 | C13: Inpatient Units (72 Beds) | D13: 0 | E13: =H13+F13+L13 -> 88164 | F13: 0 | G13: =SUM(H13,L13) -> 88164 | H13: =(I13*K13) -> 88164 | I13: 1.3 | J13: =SUM(K13) -> 67818.462 | K13: ='Hospital Program TARGET_DESIGN'!AO57/6.5 -> 67818.462 | L13: =(SUM(U13,O13,P13,Q13,R13,S13,T13)*M13) -> 0 | M13: 1.25 | N13: =SUM(O13:AA13) -> 0 | O13: 0 | P13: 0 | Q13: 0 | R13: 0 | S13: 0 | T13: 0 | U13: 0
B14: 10 | C14: Inpatient Units (72 Beds) | D14: 0 | E14: =H14+F14+L14 -> 88163.4 | F14: 0 | G14: =SUM(H14,L14) -> 88163.4 | H14: =(I14*K14) -> 88163.4 | I14: 1.3 | J14: =SUM(K14) -> 67818 | K14: 67818 | L14: =(SUM(U14,O14,P14,Q14,R14,S14,T14)*M14) -> 0 | M14: 1.25 | N14: =SUM(O14:AA14) -> 0 | O14: 0 | P14: 0 | Q14: 0 | R14: 0 | S14: 0 | T14: 0 | U14: 0
B15: 9 | C15: Inpatient Units (72 Beds) | D15: 0 | E15: =H15+F15+L15 -> 88164 | F15: 0 | G15: =SUM(H15,L15) -> 88164 | H15: =(I15*K15) -> 88164 | I15: 1.3 | J15: =SUM(K15) -> 67818.462 | K15: ='Hospital Program TARGET_DESIGN'!AO57/6.5 -> 67818.462 | L15: =(SUM(U15,O15,P15,Q15,R15,S15,T15)*M15) -> 0 | M15: 1.25 | N15: =SUM(O15:AA15) -> 0 | O15: 0 | P15: 0 | Q15: 0 | R15: 0 | S15: 0 | T15: 0 | U15: 0
B16: 8 | C16: Inpatient Units (incl PEDS, AP/PP) (72 Beds) | D16: 0 | E16: =H16+F16+L16 -> 88163.4 | F16: 0 | G16: =SUM(H16,L16) -> 88163.4 | H16: =(I16*K16) -> 88163.4 | I16: 1.3 | J16: =SUM(K16) -> 67818 | K16: 67818 | L16: =(SUM(U16,O16,P16,Q16,R16,S16,T16)*M16) -> 0 | M16: 1.25 | N16: =SUM(O16:AA16) -> 0 | O16: 0 | P16: 0 | Q16: 0 | R16: 0 | S16: 0 | T16: 0 | U16: 0
B17: 7 | C17: Inpatient Units (incl NICU, PICU, AP/PP) (108 Beds) + LDR & C-Section | D17: 0 | E17: =H17+F17+L17 -> #REF! | F17: 0 | G17: =SUM(H17,L17) -> #REF! | H17: =(I17*K17) -> #REF! | I17: 1.3 | J17: =SUM(K17) -> #REF! | K17: ='Hospital Program TARGET_DESIGN'!AO63+1 -> #REF! | L17: =(SUM(U17,O17,P17,Q17,R17,S17,T17)*M17) -> 50000 | M17: 1.25 | N17: =SUM(O17:AA17) -> 40000 | O17: 0 | P17: ='Hospital Program TARGET_DESIGN'!AO44+'Hospital Program TARGET_DESIGN'!AO45+'Hospital Program TARGET_DESIGN'!AO46 -> 40000 | Q17: 0 | R17: 0 | S17: 0 | T17: 0 | U17: 0
B18: 6 | C18: Inpatient Units (36 Beds) + Mechanical Mezzanine | D18: 0 | E18: =H18+F18+L18 -> 44082 | F18: 0 | G18: =SUM(H18,L18) -> 44082 | H18: =(I18*K18) -> 44082 | I18: 1.3 | J18: =SUM(K18) -> 33909.231 | K18: ='Hospital Program TARGET_DESIGN'!AO57/13 -> 33909.231 | L18: =(SUM(U18,O18,P18,Q18,R18,S18,T18)*M18) -> 0 | M18: 1.25 | N18: =SUM(O18:AA18) -> 0 | O18: 0 | P18: 0 | Q18: 0 | R18: 0 | S18: 0 | T18: 0 | U18: 0
B19: 5 | C19: Inpatient Units (ICU) (36 Beds) + Mechanical | D19: 0 | E19: =H19+F19+L19 -> 144082 | F19: 100000 | G19: =SUM(H19,L19) -> 44082 | H19: =(I19*K19) -> 44082 | I19: 1.3 | J19: =SUM(K19) -> 33909.231 | K19: ='Hospital Program TARGET_DESIGN'!AO57/13 -> 33909.231 | L19: =(SUM(U19,O19,P19,Q19,R19,S19,T19)*M19) -> 0 | M19: 1.25 | N19: =SUM(O19:AA19) -> 0 | O19: 0 | P19: 0 | Q19: 0 | R19: 0 | S19: 0 | T19: 0 | U19: 0
B20: 4 | C20: Inpatient Units (ICU) (36 Beds) + Surgery (OR & Prep/Rec) | D20: 0 | E20: =H20+F20+L20 -> 188332 | F20: 0 | G20: =SUM(H20,L20) -> 188332 | H20: =(I20*K20) -> 44082 | I20: 1.3 | J20: =SUM(K20) -> 33909.231 | K20: ='Hospital Program TARGET_DESIGN'!AO57/13 -> 33909.231 | L20: =(SUM(U20,O20,P20,Q20,R20,S20,T20)*M20) -> 144250 | M20: 1.25 | N20: =SUM(O20:AA20) -> 115400 | O20: 0 | P20: ='Hospital Program TARGET_DESIGN'!AO16+'Hospital Program TARGET_DESIGN'!AO17+'Hospital Program TARGET_DESIGN'!AO18+'Hospital Program TARGET_DESIGN'!AO37 -> 115400 | Q20: 0 | R20: 0 | S20: 0 | T20: 0 | U20: 0
B21: 3 | C21: Procedure Platform (Proc & Prep/Rec), PPCU, Gen Img, Obs, Cafeteria, Admin | D21: 0 | E21: =H21+F21+L21 -> 167250 | F21: 0 | G21: =SUM(H21,L21) -> 167250 | H21: =(I21*K21) -> 0 | I21: 1.3 | J21: =SUM(K21) -> 0 | K21: 0 | L21: =(SUM(U21,O21,P21,Q21,R21,S21,T21)*M21) -> 167250 | M21: 1.25 | N21: =SUM(O21:AA21) -> 133800 | O21: 0 | P21: ='Hospital Program TARGET_DESIGN'!AO21+'Hospital Program TARGET_DESIGN'!AO22+'Hospital Program TARGET_DESIGN'!AO23+'Hospital Program TARGET_DESIGN'!AO24+'Hospital Program TARGET_DESIGN'!AO25+'Hospital Program TARGET_DESIGN'!AO26+'Hospital Program TARGET_DESIGN'!AO33+'Hospital Program TARGET_DESIGN'!AO29+'Hospital Program TARGET_DESIGN'!AO30+'Hospital Program TARGET_DESIGN'!AO31+'Hospital Program TARGET_DESIGN'!AO32+'Hospital Program TARGET_DESIGN'!AO41+'Hospital Program TARGET_DESIGN'!AO50 -> 133800 | Q21: 0 | R21: 0 | S21: 0 | T21: 0 | U21: 0
B22: 2 | C22: Clinical Support + Admin | D22: 0 | E22: =H22+F22+L22 -> 163750 | F22: 0 | G22: =SUM(H22,L22) -> 163750 | H22: =(I22*K22) -> 0 | I22: 1.3 | J22: =SUM(K22) -> 0 | K22: 0 | L22: =(SUM(U22,O22,P22,Q22,R22,S22,T22)*M22) -> 163750 | M22: 1.25 | N22: =SUM(O22:AA22) -> 131000 | O22: 0 | P22: 0 | Q22: ='Hospital Program TARGET_DESIGN'!AO113+'Hospital Program TARGET_DESIGN'!AO114+'Hospital Program TARGET_DESIGN'!AO119+'Hospital Program TARGET_DESIGN'!AO125+'Hospital Program TARGET_DESIGN'!AO126+'Hospital Program TARGET_DESIGN'!AO127+'Hospital Program TARGET_DESIGN'!AO118+'Hospital Program TARGET_DESIGN'!AO120+'Hospital Program TARGET_DESIGN'!AO121 -> 37650 | R22: ='Hospital Program TARGET_DESIGN'!AO81+'Hospital Program TARGET_DESIGN'!AO82+'Hospital Program TARGET_DESIGN'!AO85+'Hospital Program TARGET_DESIGN'!AO88+'Hospital Program TARGET_DESIGN'!AO89+'Hospital Program TARGET_DESIGN'!AO90+'Hospital Program TARGET_DESIGN'!AO91 -> 86150 | S22: ='Hospital Program TARGET_DESIGN'!AO144 -> 7200 | T22: 0 | U22: 0
B23: 1 | C23: ED (73 positions), Lobby, Public Support, Site Walkway + Observation | D23: 40000 | E23: =H23+F23+L23 -> #REF! | F23: 0 | G23: =SUM(H23,L23) -> #REF! | H23: =(I23*K23) -> 0 | I23: 1.3 | J23: =SUM(K23) -> 0 | K23: 0 | L23: =(SUM(U23,O23,P23,Q23,R23,S23,T23)*M23) -> #REF! | M23: 1.25 | N23: =SUM(O23:AA23) -> #REF! | O23: ='Hospital Program TARGET_DESIGN'!AO8+'Hospital Program TARGET_DESIGN'!AO9+'Hospital Program TARGET_DESIGN'!AO12 -> 73100 | P23: 0 | Q23: ='Hospital Program TARGET_DESIGN'!AO115 -> 3000 | R23: ='Hospital Program TARGET_DESIGN'!AO92+'Hospital Program TARGET_DESIGN'!AO84 -> 5700 | S23: ='Hospital Program TARGET_DESIGN'!AO132+'Hospital Program TARGET_DESIGN'!AO131+'Hospital Program TARGET_DESIGN'!AO143+'Hospital Program TARGET_DESIGN'!#REF!+'Hospital Program TARGET_DESIGN'!#REF!+'Hospital Program TARGET_DESIGN'!AO142+'Hospital Program TARGET_DESIGN'!AO156 -> #REF! | T23: ='Hospital Program TARGET_DESIGN'!AO96+'Hospital Program TARGET_DESIGN'!AO97+'Hospital Program TARGET_DESIGN'!AO98+'Hospital Program TARGET_DESIGN'!AO101+'Hospital Program TARGET_DESIGN'!AO102+'Hospital Program TARGET_DESIGN'!AO103+'Hospital Program TARGET_DESIGN'!AO106+'Hospital Program TARGET_DESIGN'!AO107+'Hospital Program TARGET_DESIGN'!AO108 -> 48620 | U23: 31993
B24: B1 | C24: Building Support and Mechanical + Rad Onc | D24: 0 | E24: =H24+F24+L24 -> 97937.5 | F24: 18000 | G24: =SUM(H24,L24) -> 79937.5 | H24: 0 | I24: 1.3 | J24: 0 | K24: 0 | L24: =(SUM(U24,O24,P24,Q24,R24,S24,T24)*M24) -> 79937.5 | M24: 1.25 | N24: =SUM(O24:AA24) -> 63950 | O24: 0 | P24: ='Hospital Program TARGET_DESIGN'!AO53 -> 12000 | Q24: 0 | R24: 0 | S24: ='Hospital Program TARGET_DESIGN'!AO141+'Hospital Program TARGET_DESIGN'!AO146+'Hospital Program TARGET_DESIGN'!AO147+'Hospital Program TARGET_DESIGN'!AO150+'Hospital Program TARGET_DESIGN'!AO145+'Hospital Program TARGET_DESIGN'!AO153+'Hospital Program TARGET_DESIGN'!AO154+'Hospital Program TARGET_DESIGN'!AO155 -> 51950 | T24: 0 | U24: 0
B25: B2 | C25: Mechanical | D25: 0 | E25: =H25+F25+L25 -> 40738 | F25: 40738 | G25: 0 | H25: =(I25*K25) -> 0 | I25: 1.3 | J25: =SUM(K25) -> 0 | K25: 0 | L25: =(SUM(U25,O25,P25,Q25,R25,S25,T25)*M25) -> 0 | M25: 1.25 | N25: 0 | O25: 0 | P25: 0 | Q25: 0 | R25: 0 | S25: 0 | T25: 0 | U25: 0
C26: Totals | D26: =SUM(D8:D25) -> 40000 | E26: =SUM(E8:E25) -> #REF! | F26: =SUM(F8:F25) -> 234738 | G26: =SUM(G8:G25) -> #REF! | H26: =SUM(H8:H25) -> #REF! | J26: =SUM(J8:J25) -> #REF! | K26: =SUM(K8:K25) -> #REF! | L26: =SUM(L8:L25) -> #REF! | N26: =SUM(N8:N25) -> #REF! | O26: =SUM(O8:O25) -> 73100 | P26: =SUM(P8:P25) -> 301200 | Q26: =SUM(Q8:Q25) -> 40650 | R26: =SUM(R8:R25) -> 91850 | S26: =SUM(S8:S25) -> #REF! | T26: =SUM(T8:T25) -> 48620 | U26: =SUM(U8:U25) -> 31993
C27: Grossing Factor DGSF:GSF | E27: 1.5
C28: Distributed GSF | E28: =K28+O28+P28+Q28+R28+S28+T28 -> #REF! | F28: =F26/SUM(J26,N26) -> #REF! | I28: 1.5 | K28: =K26*I28 -> #REF! | M28: 1.5 | O28: =O26*M28 -> 109650 | P28: =P26*M28 -> 451800 | Q28: =Q26*M28 -> 60975 | R28: =R26*M28 -> 137775 | S28: =S26*M28 -> #REF! | T28: =T26*M28 -> 72930 | U28: =U26*M28 -> 47989.5
C31: DGSF Target Check | J31: DGSF TARGET | K31: ='Hospital Program TARGET_DESIGN'!M57 -> 435240 | N31: DGSF TARGET | O31: ='Hospital Program TARGET_DESIGN'!M6 -> 73100 | P31: ='Hospital Program TARGET_DESIGN'!M14 -> 300700 | Q31: ='Hospital Program TARGET_DESIGN'!M111 -> 40650 | R31: ='Hospital Program TARGET_DESIGN'!M79 -> 91850 | S31: ='Hospital Program TARGET_DESIGN'!M129 -> 84450 | T31: ='Hospital Program TARGET_DESIGN'!M94 -> 48620 | U31: ='Hospital Program TARGET_DESIGN'!M158 -> 0
J32: DGSF CHECK | K32: =K26-K31 -> #REF! | N32: DGSF CHECK | O32: =O26-O31 -> 0 | P32: =P26-P31 -> 500 | Q32: =Q26-Q31 -> 0 | R32: =R26-R31 -> 0 | S32: =S26-S31 -> #REF! | T32: =T26-T31 -> 0 | U32: =U26-U31 -> 31993
C34: GSF Target Check | I34: 1.3 | J34: GSF TARGET | K34: ='Hospital Program TARGET_DESIGN'!T57 -> 478764 | M34: 1.25 | N34: GSF TARGET | O34: ='Hospital Program TARGET_DESIGN'!T6 -> 80410 | P34: ='Hospital Program TARGET_DESIGN'!T14 -> 330770 | Q34: ='Hospital Program TARGET_DESIGN'!T111 -> 44715 | R34: ='Hospital Program TARGET_DESIGN'!T79 -> 101035 | S34: ='Hospital Program TARGET_DESIGN'!T129 -> 92895 | T34: ='Hospital Program TARGET_DESIGN'!T94 -> 53482 | U34: ='Hospital Program TARGET_DESIGN'!T158 -> 0
J35: GSF CHECK | K35: =K34-K28 -> #REF! | N35: GSF CHECK | O35: =O34-O28 -> -29240 | P35: =P34-P28 -> -121030 | Q35: =Q34-Q28 -> -16260 | R35: =R34-R28 -> -36740 | S35: =S34-S28 -> #REF! | T35: =T34-T28 -> -19448 | U35: =U34-U28 -> -47989.5
B40: Central Utility Plant (CUP) | F40: MEP | H40: Parking
B41: Level | C41: Program | D41: Total GSF Covered | E41: Total GSF Enclosed | F41: MEP | H41: Structured Parking
D42: 0 | E42: 0 | F42: =E42 -> 0 | H42: 0
B43: 12 Roof | C43: Cooling Towers, AHUs, Power Vent Fans | D43: 0 | E43: 10000 | F43: =E43 -> 10000 | H43: 0
B44: 12 | C44: Chillers | D44: 0 | E44: 10000 | F44: =E44 -> 10000 | H44: 0
B45: 1 | C45: Co-Generation, Electrical Services, Heat Ext, Control, Substation, Plant Support, Shop | D45: 0 | E45: 35000 | F45: =E45 -> 35000 | H45: 0
B46: B1 | C46: Pumps,Chilled & Hot Water Storage Tanks | D46: 0 | E46: 35000 | F46: =E46 -> 35000 | H46: 0
C47: Totals | D47: =SUM(D42:D46) -> 0 | E47: =SUM(E42:E46) -> 90000 | F47: =SUM(F42:F46) -> 90000 | H47: =SUM(H42:H46) -> 0
B51: North Garage - Staff Parking | F51: MEP | H51: Parking
B52: Level | C52: Program | D52: Total GSF Covered | E52: Total GSF Enclosed Min 20% Open | F52: MEP | H52: Structured Parking
B53: 8 Roof | C53: Green Roof w/ 30% Open | D53: =E55*0.7 -> 53900 | E53: 0 | H53: =E53-F53 -> 0
B54: 7 | C54: Parking / Elev. Bulkhead | D54: 0 | E54: 2500 | F54: =E54*0.5 -> 1250 | H54: =E54-F54 -> 1250
...

Sheet Load Assumptions (SEQRA)
B2: NYUL LI - Mellvile HQ Load Assumptions (SEQRA)
B4: UPDATED: 11/07/2025
B6: NYUL LI Melville HQ Campus | C6: Units | E6: GSF | G6: Water Metric* | I6: Gal/Day | K6: Sewer Metric* | M6: Gal/Day | O6: Power Demand | Q6: kW | S6: Notes
S8: GSF Values are based on Target Design Values
B9: Hospital
B10: Inpatient Beds | C10: ='Hospital Program TARGET_DESIGN'!K55 -> 574 | D10: Beds | E10: ='Hospital Program per Floor'!K28 -> #REF! | G10: 300 | H10: gal per bed | I10: =$C10*G10 -> 172200 | K10: =G10*0.9 -> 270 | L10: gal per bed | M10: =$C10*K10 -> 154980
B11: Emergency Department & Observation | C11: 73 | 16 | D11: Positions | Beds | E11: ='Hospital Program per Floor'!O28 -> 109650 | G11: 0.21 | H11: gal per GSF | I11: =$E11*G11 -> 23026.5 | K11: =G11*0.9 -> 0.189 | L11: gal per GSF | M11: =$E11*K11 -> 20723.85
B12: Diagnostic & Treatment | C12: 23 | D12: ORs | E12: ='Hospital Program per Floor'!P28 -> 451800 | G12: 0.21 | H12: gal per GSF | I12: =$E12*G12 -> 94878 | K12: =G12*0.9 -> 0.189 | L12: gal per GSF | M12: =$E12*K12 -> 85390.2
B13: Admin & Support | E13: ='Hospital Program per Floor'!Q28+'Hospital Program per Floor'!R28+'Hospital Program per Floor'!S28+'Hospital Program per Floor'!T28 -> #REF! | G13: 0.21 | H13: gal per GSF | I13: =$E13*G13 -> #REF! | K13: =G13*0.9 -> 0.189 | L13: gal per GSF | M13: =$E13*K13 -> #REF!
B14: Phase 1 Hospital Sub-Total | E14: =SUM(E10:E13) -> #REF! | I14: =SUM(I10:I13) -> #REF! | M14: =SUM(M10:M13) -> #REF! | O14: 7 | P14: W per GSF | Q14: =($E14*O14)/1000 -> #REF! | S14: JBB to review/confirm the W per GSF metric assumptions
B16: Central Utility Plant
B17: Central Utility Plant (Cooling Towers - Peak Day [NYU Only]) | G17: - | H17: - | I17: 216368 | K17: - | L17: - | M17: 35454 | O17: - | P17: - | Q17: -
B18: Central Utility Plant (Cooling Towers - Avg Summer Day [NYU Only]) | G18: - | H18: - | I18: 179495 | K18: - | L18: - | M18: 29412 | O18: - | P18: - | Q18: -
B19: Central Utility Plant (Core and Shell) | E19: ='Hospital Program per Floor'!E47 -> 90000 | G19: - | H19: - | I19: - | K19: - | L19: - | M19: - | O19: 2.5 | P19: W per GSF | Q19: =($E19*O19)/1000 -> 225
B20: Central Utility Plant (Equipment Infrastructure, Connected Load) | G20: - | H20: - | I20: - | K20: - | L20: - | M20: - | O20: - | P20: - | Q20: 11500
B21: Central Utility Plant (Equipment Infrastructure, Day One Design Day Load) | G21: - | H21: - | I21: - | K21: - | L21: - | M21: - | O21: - | P21: - | Q21: 7750
B22: Central Utility Plant (Equipment Infrastructure, Day One 100% Elec Heat) | G22: - | H22: - | I22: - | K22: - | L22: - | M22: - | O22: - | P22: - | Q22: 20250 | S22: Note: This load is shown for reference only and not included in total loads.
B23: Phase 1 CUP | E23: =SUM(E19) -> 90000 | I23: =I17 -> 216368 | M23: =M17 -> 35454 | Q23: =Q19+Q21 -> 7975 | S23: This number is if hot water boilers are electric.
B25: Structured Parking
B26: North Garage - Staff Parking | E26: ='Hospital Program per Floor'!E62 -> 535500 | G26: 0 | H26: - | I26: =$E26*G26 -> 0 | K26: =G26*0.9 -> 0 | L26: - | M26: =$E26*K26 -> 0
B27: South Garage - Visitor Parking | E27: ='Hospital Program per Floor'!E77 -> 357000 | G27: 0 | H27: - | I27: =$E27*G27 -> 0 | K27: =G27*0.9 -> 0 | L27: - | M27: =$E27*K27 -> 0
B28: Phase 1 Structured Parking | E28: =SUM(E26:E27) -> 892500 | I28: =SUM(I26:I27) -> 0 | M28: =SUM(M26:M27) -> 0 | O28: 3.75 | P28: W per GSF | Q28: =($E28*O28)/1000 -> 3346.875 | S28: JBB to review/confirm the W per GSF metric assumptions
B30: Site Development
B31: Irrigation and Site Lighting (excluding building SF) | E31: 630733 | G31: 0.0031 | H31: gal | I31: =E31*G31 -> 1955.2723 | K31: 0.0028 | L31: gal per GSF | M31: =E31*K31 -> 1766.0524 | S31: AREA CLAC ASSUMPTION: HQ1 Site Area (1,030,733SF)
B32: Phase 1 Site Development | E32: =SUM(E31) -> 630733 | I32: =SUM(I31) -> 1955.2723 | M32: =SUM(M31) -> 1766.0524 | O32: 0.05 | P32: W per GSF | Q32: =($E32*O32)/1000 -> 31.53665 | S32: L1 Building Areas (265,000SF : Hospital + 135,000SF : Parking Garages)
S33: Note: Irrigation value is average gallon per day over full year for Entire Site.
S34: XXXX gal/year (May - September) No irrigation assumed Jan. - April & Oct. - Dec.
B35: Phase 1 Sub-Total | E35: =E14+E23+E28 -> #REF! | I35: =I14+I23+I28 -> #REF! | M35: =M14+M23+M28 -> #REF! | Q35: =Q14+Q23+Q28 -> #REF!
B36: Phase 1 Sub-Total - Site | E36: =E32 -> 630733 | I36: =I32 -> 1955.2723 | M36: =M32 -> 1766.0524 | Q36: =Q32 -> 31.53665
B38: Phase 2 Buildings
B39: Student / Staff Housing | C39: ='Campus MASTER PLAN'!E43 -> 240 | D39: Units | E39: ='Campus MASTER PLAN'!I43 -> 200000 | G39: 130 | H39: gal per unit | I39: =$C39*G39 -> 31200 | K39: =G39*0.9 -> 117 | L39: gal per unit | M39: =$C39*K39 -> 28080 | O39: 1.2 | P39: W per GSF | Q39: =($E39*O39)/1000 -> 240
B40: Academic/Research | E40: ='Campus MASTER PLAN'!I28+'Campus MASTER PLAN'!I32 -> 90000 | G40: 0.13 | H40: gal per GSF | I40: =$E40*G40 -> 11700 | K40: =G40*0.9 -> 0.117 | L40: gal per GSF | M40: =$E40*K40 -> 10530 | O40: 5 | P40: W per GSF | Q40: =($E40*O40)/1000 -> 450
B41: Corporate Offices | E41: ='Campus MASTER PLAN'!I36 -> 70000 | G41: 0.13 | H41: gal per GSF | I41: =$E41*G41 -> 9100 | K41: =G41*0.9 -> 0.117 | L41: gal per GSF | M41: =$E41*K41 -> 8190 | O41: 2.25 | P41: W per GSF | Q41: =($E41*O41)/1000 -> 157.5
B42: Medical Office Building (MOB) | E42: ='Campus MASTER PLAN'!I47 -> 125000 | G42: 0.13 | H42: gal per GSF | I42: =$E42*G42 -> 16250 | K42: =G42*0.9 -> 0.117 | L42: gal per GSF | M42: =$E42*K42 -> 14625 | O42: 1.5 | P42: W per GSF | Q42: =($E42*O42)/1000 -> 187.5
B43: Phase 2 Buildings Sub-Total | E43: =SUM(E39:E42) -> 485000 | I43: =SUM(I39:I42) -> 68250 | M43: =SUM(M39:M42) -> 61425 | Q43: =SUM(Q39:Q42) -> 1035
B45: Central Utility Plant
B46: Central Utility Plant (Cooling Towers - Peak Day) | G46: - | H46: - | I46: 120989 | K46: - | L46: - | M46: 19825 | O46: - | P46: - | Q46: -
B47: Central Utility Plant (Cooling Towers - Avg Summer Day) | G47: - | H47: - | I47: 100937 | K47: - | L47: - | M47: 16539 | O47: - | P47: - | Q47: -
B48: Central Utility Plant (Core and Shell) | E48: 10000 | G48: - | H48: - | I48: - | K48: - | L48: - | M48: - | O48: 2.5 | P48: W per GSF | Q48: =($E48*O48)/1000 -> 25
B49: Central Utility Plant (Equipment Infrastructure, Connected Load) | G49: - | H49: - | I49: - | K49: - | L49: - | M49: - | O49: - | P49: - | Q49: 4000
...
